Workbook
Name age: #REF!
Name namecount: #REF!
Name Network: #REF!
Name Slicer_Accounts1: #N/A
Name Slicer_Date11: #N/A
Name Slicer_Year: #N/A

Sheet DATA
A1: Year | B1: Month | C1: Month (number) | D1: Passengers (M) | E1: Passengers | F1: Load Factor | G1: On Time | H1: Customer Satisfaction | I1: CO2 Emissions | L1: Column Labels
A2: 2025 | B2: April | C2: 4 | D2: 18.3 | E2: =D2*1000000 -> 18300000 | F2: 0.93 | G2: 0.9 | H2: 0.9 | I2: 65g | L2: 2021 | M2: 2022 | N2: 2023 | O2: 2024 | P2: 2025 | Q2: (blank) | R2: Grand Total
A3: 2025 | B3: March | C3: 3 | D3: 15 | E3: =D3*1000000 -> 15000000 | F3: 0.93 | G3: 0.92 | H3: 0.92 | I3: 64g | K3: Sum of Passengers | L3: 52700000 | M3: 160400000 | N3: 181700000 | O3: 197100000 | P3: 58300000 | R3: 650200000
A4: 2025 | B4: February | C4: 2 | D4: 12.6 | E4: =D4*1000000 -> 12600000 | F4: 0.92 | G4: 0.91 | H4: 0.89 | I4: 64g
A5: 2025 | B5: January | C5: 1 | D5: 12.4 | E5: =D5*1000000 -> 12400000 | F5: 0.91 | G5: 0.85 | H5: 0.86 | I5: 65g
A6: 2024 | B6: December | C6: 12 | D6: 13.6 | E6: =D6*1000000 -> 13600000 | F6: 0.92 | G6: 0.84 | H6: 0.85 | I6: 65g
A7: 2024 | B7: November | C7: 11 | D7: 13 | E7: =D7*1000000 -> 13000000 | F7: 0.92 | G7: 0.9 | H7: 0.87 | I7: 65g | L7: Column Labels
A8: 2024 | B8: October | C8: 10 | D8: 18.3 | E8: =D8*1000000 -> 18300000 | F8: 0.93 | G8: 0.87 | H8: 0.85 | I8: 65g | L8: 2021 | M8: 2022 | N8: 2023 | O8: 2024 | P8: 2025 | Q8: (blank) | R8: Grand Total
A9: 2024 | B9: September | C9: 9 | D9: 19.1 | E9: =D9*1000000 -> 19100000 | F9: 0.94 | G9: 0.85 | H9: 0.85 | I9: 65g | K9: Average of Load Factor | L9: 0.828 | M9: 0.91166667 | N9: 0.93416667 | O9: 0.9325 | P9: 0.9225 | R9: 0.91488889
A10: 2024 | B10: August | C10: 8 | D10: 20.5 | E10: =D10*1000000 -> 20500000 | F10: 0.96 | G10: 0.86 | H10: 0.85 | I10: 64g
A11: 2024 | B11: July | C11: 7 | D11: 20.2 | E11: =D11*1000000 -> 20200000 | F11: 0.96 | G11: 0.85 | H11: 0.83 | I11: 64g
A12: 2024 | B12: June | C12: 6 | D12: 19.3 | E12: =D12*1000000 -> 19300000 | F12: 0.95 | G12: 0.87 | H12: 0.84 | I12: 65g
A13: 2024 | B13: May | C13: 5 | D13: 18.9 | E13: =D13*1000000 -> 18900000 | F13: 0.95 | G13: 0.88 | H13: 0.86 | I13: 65g
A14: 2024 | B14: April | C14: 4 | D14: 17.3 | E14: =D14*1000000 -> 17300000 | F14: 0.92 | G14: 0.88 | H14: 0.88 | I14: 65g | L14: Column Labels
A15: 2024 | B15: March | C15: 3 | D15: 13.6 | E15: =D15*1000000 -> 13600000 | F15: 0.93 | G15: 0.91 | H15: 0.88 | I15: 65g | L15: 2021 | M15: 2022 | N15: 2023 | O15: 2024 | P15: 2025 | Q15: (blank) | R15: Grand Total
A16: 2024 | B16: February | C16: 2 | D16: 11.1 | E16: =D16*1000000 -> 11100000 | F16: 0.92 | G16: 0.92 | H16: 0.89 | I16: 64g | K16: Average of On Time | L16: 0.9 | M16: 0.8475 | N16: 0.86416667 | O16: 0.875 | P16: 0.895 | R16: 0.86933333
A17: 2024 | B17: January | C17: 1 | D17: 12.2 | E17: =D17*1000000 -> 12200000 | F17: 0.89 | G17: 0.87 | H17: 0.88 | I17: 67g
A18: 2023 | B18: December | C18: 12 | D18: 12.5 | E18: =D18*1000000 -> 12500000 | F18: 0.91 | G18: 0.83 | H18: 0.85 | I18: 67g
A19: 2023 | B19: November | C19: 11 | D19: 11.7 | E19: =D19*1000000 -> 11700000 | F19: 0.92 | G19: 0.89 | H19: 0.87 | I19: 66g
A20: 2023 | B20: October | C20: 10 | D20: 17.1 | E20: =D20*1000000 -> 17100000 | F20: 0.93 | G20: 0.86 | H20: 0.86 | I20: 66g | L20: Column Labels
A21: 2023 | B21: September | C21: 9 | D21: 17.4 | E21: =D21*1000000 -> 17400000 | F21: 0.94 | G21: 0.87 | H21: 0.85 | I21: 66g | L21: 2021 | M21: 2022 | N21: 2023 | O21: 2024 | P21: 2025 | Q21: (blank) | R21: Grand Total
A22: 2023 | B22: August | C22: 8 | D22: 18.9 | E22: =D22*1000000 -> 18900000 | F22: 0.96 | G22: 0.86 | H22: 0.84 | I22: 65g | K22: Average of Customer Satisfaction | L22: 0.89 | M22: 0.85416667 | N22: 0.85916667 | O22: 0.86083333 | P22: 0.8925 | R22: 0.86466667
A23: 2023 | B23: July | C23: 7 | D23: 18.7 | E23: =D23*1000000 -> 18700000 | F23: 0.96 | G23: 0.84 | H23: 0.82 | I23: 65g
A24: 2023 | B24: June | C24: 6 | D24: 17.4 | E24: =D24*1000000 -> 17400000 | F24: 0.95 | G24: 0.86 | H24: 0.84 | I24: 66g
A25: 2023 | B25: May | C25: 5 | D25: 17 | E25: =D25*1000000 -> 17000000 | F25: 0.94 | G25: 0.88 | H25: 0.86 | I25: 66g | K25: Sum of Passengers | L25: Column Labels
A26: 2023 | B26: April | C26: 4 | D26: 16 | E26: =D26*1000000 -> 16000000 | F26: 0.94 | G26: 0.86 | H26: 0.85 | I26: 66g | K26: Row Labels | L26: 2021 | M26: 2022 | N26: 2023 | O26: 2024 | P26: 2025 | Q26: (blank) | R26: Grand Total
A27: 2023 | B27: March | C27: 3 | D27: 12.6 | E27: =D27*1000000 -> 12600000 | F27: 0.93 | G27: 0.87 | H27: 0.88 | I27: 66g | K27: January | M27: 7000000 | N27: 11800000 | O27: 12200000 | P27: 12400000 | R27: 43400000
A28: 2023 | B28: February | C28: 2 | D28: 10.6 | E28: =D28*1000000 -> 10600000 | F28: 0.92 | G28: 0.89 | H28: 0.9 | I28: 65g | K28: February | M28: 8700000 | N28: 10600000 | O28: 11100000 | P28: 12600000 | R28: 43000000
A29: 2023 | B29: January | C29: 1 | D29: 11.8 | E29: =D29*1000000 -> 11800000 | F29: 0.91 | G29: 0.86 | H29: 0.89 | I29: 66g | K29: March | M29: 11200000 | N29: 12600000 | O29: 13600000 | P29: 15000000 | R29: 52400000
A30: 2022 | B30: December | C30: 12 | D30: 11.5 | E30: =D30*1000000 -> 11500000 | F30: 0.92 | G30: 0.76 | H30: 0.87 | I30: 66g | K30: April | M30: 14200000 | N30: 16000000 | O30: 17300000 | P30: 18300000 | R30: 65800000
A31: 2022 | B31: November | C31: 11 | D31: 11.2 | E31: =D31*1000000 -> 11200000 | F31: 0.92 | G31: 0.87 | H31: 0.88 | I31: 66g | K31: May | M31: 15400000 | N31: 17000000 | O31: 18900000 | R31: 51300000
A32: 2022 | B32: October | C32: 10 | D32: 15.7 | E32: =D32*1000000 -> 15700000 | F32: 0.94 | G32: 0.82 | H32: 0.83 | I32: 66g | K32: June | M32: 15900000 | N32: 17400000 | O32: 19300000 | R32: 52600000
A33: 2022 | B33: September | C33: 9 | D33: 15.9 | E33: =D33*1000000 -> 15900000 | F33: 0.94 | G33: 0.81 | H33: 0.82 | I33: 66g | K33: July | M33: 16800000 | N33: 18700000 | O33: 20200000 | R33: 55700000
A34: 2022 | B34: August | C34: 8 | D34: 16.9 | E34: =D34*1000000 -> 16900000 | F34: 0.96 | G34: 0.82 | H34: 0.82 | I34: 65g | K34: August | L34: 11100000 | M34: 16900000 | N34: 18900000 | O34: 20500000 | R34: 67400000
A35: 2022 | B35: July | C35: 7 | D35: 16.8 | E35: =D35*1000000 -> 16800000 | F35: 0.96 | G35: 0.79 | H35: 0.81 | I35: 65g | K35: September | L35: 10600000 | M35: 15900000 | N35: 17400000 | O35: 19100000 | R35: 63000000
A36: 2022 | B36: June | C36: 6 | D36: 15.9 | E36: =D36*1000000 -> 15900000 | F36: 0.95 | G36: 0.81 | H36: 0.79 | I36: 65g | K36: October | L36: 11300000 | M36: 15700000 | N36: 17100000 | O36: 18300000 | R36: 62400000
A37: 2022 | B37: May | C37: 5 | D37: 15.4 | E37: =D37*1000000 -> 15400000 | F37: 0.92 | G37: 0.86 | H37: 0.86 | I37: 66g | K37: November | L37: 10200000 | M37: 11200000 | N37: 11700000 | O37: 13000000 | R37: 46100000
A38: 2022 | B38: April | C38: 4 | D38: 14.2 | E38: =D38*1000000 -> 14200000 | F38: 0.91 | G38: 0.85 | H38: 0.85 | I38: 67g | K38: December | L38: 9500000 | M38: 11500000 | N38: 12500000 | O38: 13600000 | R38: 47100000
A39: 2022 | B39: March | C39: 3 | D39: 11.2 | E39: =D39*1000000 -> 11200000 | F39: 0.87 | G39: 0.92 | H39: 0.91 | I39: 69g | K39: (blank)
A40: 2022 | B40: February | C40: 2 | D40: 8.7 | E40: =D40*1000000 -> 8700000 | F40: 0.86 | G40: 0.93 | H40: 0.9 | I40: 70g | K40: Grand Total | L40: 52700000 | M40: 160400000 | N40: 181700000 | O40: 197100000 | P40: 58300000 | R40: 650200000
...

Sheet Facts & Figures
C9: Passengers by Month | H9: Customer Satisfaction by Month
C10: Month | D10: Passengers 2023 | E10: Passengers 2024 | F10: Variance | H10: Month | I10: Satisfaction 2023 | J10: Satisfaction 2024 | K10: Variance
C11: =DATA!K27 -> January | D11: =GETPIVOTDATA("Passengers",DATA!$K$25,"Year",2023,"Month","January") -> 11800000 | E11: =GETPIVOTDATA("Passengers",DATA!$K$25,"Year",2024,"Month","January") -> 12200000 | F11: =E11-D11 -> 400000 | H11: =DATA!K48 -> January | I11: =GETPIVOTDATA("Customer Satisfaction",DATA!$K$46,"Year",2023,"Month","January") -> 0.89 | J11: =GETPIVOTDATA("Customer Satisfaction",DATA!$K$46,"Year",2024,"Month","January") -> 0.88 | K11: =J11-I11 -> -0.01
C12: =DATA!K28 -> February | D12: =GETPIVOTDATA("Passengers",DATA!$K$25,"Year",2023,"Month","February") -> 10600000 | E12: =GETPIVOTDATA("Passengers",DATA!$K$25,"Year",2024,"Month","February") -> 11100000 | F12: =E12-D12 -> 500000 | H12: =DATA!K49 -> February | I12: =GETPIVOTDATA("Customer Satisfaction",DATA!$K$46,"Year",2023,"Month","February") -> 0.9 | J12: =GETPIVOTDATA("Customer Satisfaction",DATA!$K$46,"Year",2024,"Month","February") -> 0.89 | K12: =J12-I12 -> -0.01
C13: =DATA!K29 -> March | D13: =GETPIVOTDATA("Passengers",DATA!$K$25,"Year",2023,"Month","March") -> 12600000 | E13: =GETPIVOTDATA("Passengers",DATA!$K$25,"Year",2024,"Month","March") -> 13600000 | F13: =E13-D13 -> 1000000 | H13: =DATA!K50 -> March | I13: =GETPIVOTDATA("Customer Satisfaction",DATA!$K$46,"Year",2023,"Month","March") -> 0.88 | J13: =GETPIVOTDATA("Customer Satisfaction",DATA!$K$46,"Year",2024,"Month","March") -> 0.88 | K13: =J13-I13 -> 0
C14: =DATA!K30 -> April | D14: =GETPIVOTDATA("Passengers",DATA!$K$25,"Year",2023,"Month","April") -> 16000000 | E14: =GETPIVOTDATA("Passengers",DATA!$K$25,"Year",2024,"Month","April") -> 17300000 | F14: =E14-D14 -> 1300000 | H14: =DATA!K51 -> April | I14: =GETPIVOTDATA("Customer Satisfaction",DATA!$K$46,"Year",2023,"Month","April") -> 0.85 | J14: =GETPIVOTDATA("Customer Satisfaction",DATA!$K$46,"Year",2024,"Month","April") -> 0.88 | K14: =J14-I14 -> 0.03
C15: =DATA!K31 -> May | D15: =GETPIVOTDATA("Passengers",DATA!$K$25,"Year",2023,"Month","May") -> 17000000 | E15: =GETPIVOTDATA("Passengers",DATA!$K$25,"Year",2024,"Month","May") -> 18900000 | F15: =E15-D15 -> 1900000 | H15: =DATA!K52 -> May | I15: =GETPIVOTDATA("Customer Satisfaction",DATA!$K$46,"Year",2023,"Month","May") -> 0.86 | J15: =GETPIVOTDATA("Customer Satisfaction",DATA!$K$46,"Year",2024,"Month","May") -> 0.86 | K15: =J15-I15 -> 0
C16: =DATA!K32 -> June | D16: =GETPIVOTDATA("Passengers",DATA!$K$25,"Year",2023,"Month","June") -> 17400000 | E16: =GETPIVOTDATA("Passengers",DATA!$K$25,"Year",2024,"Month","June") -> 19300000 | F16: =E16-D16 -> 1900000 | H16: =DATA!K53 -> June | I16: =GETPIVOTDATA("Customer Satisfaction",DATA!$K$46,"Year",2023,"Month","June") -> 0.84 | J16: =GETPIVOTDATA("Customer Satisfaction",DATA!$K$46,"Year",2024,"Month","June") -> 0.84 | K16: =J16-I16 -> 0
C17: =DATA!K33 -> July | D17: =GETPIVOTDATA("Passengers",DATA!$K$25,"Year",2023,"Month","July") -> 18700000 | E17: =GETPIVOTDATA("Passengers",DATA!$K$25,"Year",2024,"Month","July") -> 20200000 | F17: =E17-D17 -> 1500000 | H17: =DATA!K54 -> July | I17: =GETPIVOTDATA("Customer Satisfaction",DATA!$K$46,"Year",2023,"Month","July") -> 0.82 | J17: =GETPIVOTDATA("Customer Satisfaction",DATA!$K$46,"Year",2024,"Month","July") -> 0.83 | K17: =J17-I17 -> 0.01
C18: =DATA!K34 -> August | D18: =GETPIVOTDATA("Passengers",DATA!$K$25,"Year",2023,"Month","August") -> 18900000 | E18: =GETPIVOTDATA("Passengers",DATA!$K$25,"Year",2024,"Month","August") -> 20500000 | F18: =E18-D18 -> 1600000 | H18: =DATA!K55 -> August | I18: =GETPIVOTDATA("Customer Satisfaction",DATA!$K$46,"Year",2023,"Month","August") -> 0.84 | J18: =GETPIVOTDATA("Customer Satisfaction",DATA!$K$46,"Year",2024,"Month","August") -> 0.85 | K18: =J18-I18 -> 0.01
C19: =DATA!K35 -> September | D19: =GETPIVOTDATA("Passengers",DATA!$K$25,"Year",2023,"Month","September") -> 17400000 | E19: =GETPIVOTDATA("Passengers",DATA!$K$25,"Year",2024,"Month","September") -> 19100000 | F19: =E19-D19 -> 1700000 | H19: =DATA!K56 -> September | I19: =GETPIVOTDATA("Customer Satisfaction",DATA!$K$46,"Year",2023,"Month","September") -> 0.85 | J19: =GETPIVOTDATA("Customer Satisfaction",DATA!$K$46,"Year",2024,"Month","September") -> 0.85 | K19: =J19-I19 -> 0
C20: =DATA!K36 -> October | D20: =GETPIVOTDATA("Passengers",DATA!$K$25,"Year",2023,"Month","October") -> 17100000 | E20: =GETPIVOTDATA("Passengers",DATA!$K$25,"Year",2024,"Month","October") -> 18300000 | F20: =E20-D20 -> 1200000 | H20: =DATA!K57 -> October | I20: =GETPIVOTDATA("Customer Satisfaction",DATA!$K$46,"Year",2023,"Month","October") -> 0.86 | J20: =GETPIVOTDATA("Customer Satisfaction",DATA!$K$46,"Year",2024,"Month","October") -> 0.85 | K20: =J20-I20 -> -0.01
C21: =DATA!K37 -> November | D21: =GETPIVOTDATA("Passengers",DATA!$K$25,"Year",2023,"Month","November") -> 11700000 | E21: =GETPIVOTDATA("Passengers",DATA!$K$25,"Year",2024,"Month","November") -> 13000000 | F21: =E21-D21 -> 1300000 | H21: =DATA!K58 -> November | I21: =GETPIVOTDATA("Customer Satisfaction",DATA!$K$46,"Year",2023,"Month","November") -> 0.87 | J21: =GETPIVOTDATA("Customer Satisfaction",DATA!$K$46,"Year",2024,"Month","November") -> 0.87 | K21: =J21-I21 -> 0
C22: =DATA!K38 -> December | D22: =GETPIVOTDATA("Passengers",DATA!$K$25,"Year",2023,"Month","December") -> 12500000 | E22: =GETPIVOTDATA("Passengers",DATA!$K$25,"Year",2024,"Month","December") -> 13600000 | F22: =E22-D22 -> 1100000 | H22: =DATA!K59 -> December | I22: =GETPIVOTDATA("Customer Satisfaction",DATA!$K$46,"Year",2023,"Month","December") -> 0.85 | J22: =GETPIVOTDATA("Customer Satisfaction",DATA!$K$46,"Year",2024,"Month","December") -> 0.85 | K22: =J22-I22 -> 0
C23: Grand Total | D23: =SUM(D11:D22) -> 181700000 | E23: =SUM(E11:E22) -> 197100000 | F23: =SUM(F11:F22) -> 15400000 | H23: Grand Total | I23: =AVERAGE(I11:I22) -> 0.85916667 | J23: =AVERAGE(J11:J22) -> 0.86083333 | K23: =AVERAGE(K11:K22) -> 0.0016666667
C39: Data source: https://corporate.ryanair.com/facts-figures/key-stats/

Sheet Customer Satisfaction Tracker
B2: Tracking Start Date | Y2: 100% Satisfaction
B3: 45658 | Y3: =COUNTIF(C22:W22,"100%") -> 8
B5: Best Satisfaction | Y5: 50% Satisfaction
B6: =_xlfn.XLOOKUP(MAX(X14:X19),X14:X19,B14:B19) -> Pricing policy | Y6: =COUNTIF(C22:W22,">50%") -> 17
B8: Worst Habit | Y8: 0% Satisfaction
B9: =_xlfn.XLOOKUP(MIN(X14:X19),X14:X19,B14:B19) -> Flight schedule & routes | Y9: =COUNTIF(C22:W22,"0%") -> 1
C11: Week 1 | J11: Week 2 | Q11: Week 3
C12: =$B$3 -> 45658 | D12: =C12+1 -> 45659 | E12: =D12+1 -> 45660 | F12: =E12+1 -> 45661 | G12: =F12+1 -> 45662 | H12: =G12+1 -> 45663 | I12: =H12+1 -> 45664 | J12: =I12+1 -> 45665 | K12: =J12+1 -> 45666 | ... W12: =V12+1 -> 45678
B13: Passenger satisfaction | C13: {=_xlfn.SEQUENCE(,21)} -> 1 | D13: 2 | E13: 3 | F13: 4 | G13: 5 | H13: 6 | I13: 7 | J13: 8 | K13: 9 | L13: 10 | M13: 11 | N13: 12 | O13: 13 | P13: 14 | Q13: 15 | R13: 16 | S13: 17 | T13: 18 | U13: 19 | V13: 20 | W13: 21 | Y13: Total Completed
B14: Pricing policy | C14: TRUE | D14: TRUE | E14: TRUE | F14: TRUE | G14: TRUE | H14: TRUE | I14: TRUE | J14: TRUE | K14: TRUE | L14: TRUE | M14: TRUE | N14: FALSE | O14: TRUE | P14: TRUE | Q14: FALSE | R14: TRUE | S14: FALSE | T14: TRUE | U14: TRUE | V14: TRUE | W14: TRUE | X14: =COUNTIF(C14:W14,"TRUE") -> 18 | Y14: =REPT("|",X14*4) -> ||||||||||||||||||||||||||||||||||||||||||||||||||||||||||||||||||||||||
B15: Website | C15: TRUE | D15: TRUE | E15: TRUE | F15: TRUE | G15: TRUE | H15: TRUE | I15: FALSE | J15: TRUE | K15: TRUE | L15: FALSE | M15: TRUE | N15: TRUE | O15: TRUE | P15: TRUE | Q15: FALSE | R15: FALSE | S15: TRUE | T15: TRUE | U15: TRUE | V15: TRUE | W15: TRUE | X15: =COUNTIF(C15:W15,"TRUE") -> 17 | Y15: =REPT("|",X15*4) -> ||||||||||||||||||||||||||||||||||||||||||||||||||||||||||||||||||||
B16: Flight schedule & routes | C16: TRUE | D16: TRUE | E16: FALSE | F16: TRUE | G16: FALSE | H16: FALSE | I16: TRUE | J16: TRUE | K16: TRUE | L16: FALSE | M16: FALSE | N16: TRUE | O16: TRUE | P16: TRUE | Q16: FALSE | R16: FALSE | S16: TRUE | T16: TRUE | U16: FALSE | V16: TRUE | W16: TRUE | X16: =COUNTIF(C16:W16,"TRUE") -> 13 | Y16: =REPT("|",X16*4) -> ||||||||||||||||||||||||||||||||||||||||||||||||||||
B17: Airport services | C17: TRUE | D17: TRUE | E17: TRUE | F17: TRUE | G17: TRUE | H17: TRUE | I17: TRUE | J17: TRUE | K17: TRUE | L17: FALSE | M17: TRUE | N17: TRUE | O17: FALSE | P17: TRUE | Q17: FALSE | R17: TRUE | S17: TRUE | T17: TRUE | U17: TRUE | V17: TRUE | W17: FALSE | X17: =COUNTIF(C17:W17,"TRUE") -> 17 | Y17: =REPT("|",X17*4) -> ||||||||||||||||||||||||||||||||||||||||||||||||||||||||||||||||||||
B18: During flight | C18: TRUE | D18: TRUE | E18: TRUE | F18: TRUE | G18: FALSE | H18: TRUE | I18: FALSE | J18: TRUE | K18: TRUE | L18: FALSE | M18: TRUE | N18: FALSE | O18: TRUE | P18: TRUE | Q18: FALSE | R18: TRUE | S18: FALSE | T18: TRUE | U18: FALSE | V18: TRUE | W18: FALSE | X18: =COUNTIF(C18:W18,"TRUE") -> 13 | Y18: =REPT("|",X18*4) -> ||||||||||||||||||||||||||||||||||||||||||||||||||||
B19: After landing | C19: TRUE | D19: TRUE | E19: TRUE | F19: TRUE | G19: TRUE | H19: FALSE | I19: FALSE | J19: TRUE | K19: TRUE | L19: FALSE | M19: TRUE | N19: TRUE | O19: TRUE | P19: TRUE | Q19: FALSE | R19: TRUE | S19: FALSE | T19: TRUE | U19: TRUE | V19: TRUE | W19: TRUE | X19: =COUNTIF(C19:W19,"TRUE") -> 16 | Y19: =REPT("|",X19*4) -> ||||||||||||||||||||||||||||||||||||||||||||||||||||||||||||||||
B21: Task Completed | C21: =COUNTIF(C14:C19,"TRUE") -> 6 | D21: =COUNTIF(D14:D19,"TRUE") -> 6 | E21: =COUNTIF(E14:E19,"TRUE") -> 5 | F21: =COUNTIF(F14:F19,"TRUE") -> 6 | G21: =COUNTIF(G14:G19,"TRUE") -> 4 | H21: =COUNTIF(H14:H19,"TRUE") -> 4 | I21: =COUNTIF(I14:I19,"TRUE") -> 3 | J21: =COUNTIF(J14:J19,"TRUE") -> 6 | ... W21: =COUNTIF(W14:W19,"TRUE") -> 4
B22: % Completed | C22: =C21/COUNTA(C14:C19) -> 1 | D22: =D21/COUNTA(D14:D19) -> 1 | E22: =E21/COUNTA(E14:E19) -> 0.83333333 | F22: =F21/COUNTA(F14:F19) -> 1 | G22: =G21/COUNTA(G14:G19) -> 0.66666667 | H22: =H21/COUNTA(H14:H19) -> 0.66666667 | I22: =I21/COUNTA(I14:I19) -> 0.5 | J22: =J21/COUNTA(J14:J19) -> 1 | ... W22: =W21/COUNTA(W14:W19) -> 0.66666667

Sheet Company Balance Sheet
D8: Actual (€)
C9: Current assets | D9: 6521.1
C10: Cash and cash equivalents | D10: 35.8
C11: Loans and receivables due from subsidiaries | D11: 6485.3
C12: Current liabilities | D12: 105.6
C13: Amounts due to subsidiaries | D13: 105.6
C14: Non-current assets | D14: 567.2
C15: Investments in subsidiaries | D15: 567.2
C16: Shareholders’ equity | D16: 6982.7
C17: Issued share capital | D17: 20.6
C18: Other reserves | D18: 105.6
C19: Other undenominated capital reserve | D19: 10.5
C20: Retained earnings | D20: 2733.6
C21: Share premium account | D21: 4112.4
A24: Data source: https://investor.ryanair.com/wp-content/uploads/2024/06/Ryanair-2024-Annual-Report.pdf
